Workbook

Sheet Presión de Viento
A1: PLANILLA DE CARGAS DE VIENTO - SPRFV - NCh432:2025
A2: ="Galpón industrial - "&IF(C10=1,"Techo a 1 agua","Techo a 2 aguas")&" - Edificio cerrado" -> Galpón industrial - Techo a 2 aguas - Edificio cerrado
A4: 1. PARÁMETROS GEOMÉTRICOS DEL GALPÓN
A5: Parámetro | B5: Símbolo | C5: Valor | D5: Unidad | E5: Referencia / Notas
A6: Largo del galpón | B6: L | C6: 83.5 | D6: m | E6: Dimensión paralela a la cumbrera → modificar aquí
A7: Ancho del galpón (⊥ cumbrera) | B7: B | C7: 50 | D7: m | E7: Dimensión perpendicular a la cumbrera → modificar aquí
A8: Altura al alero | B8: h_e | C8: 7.53 | D8: m | E8: Altura al alero (desde nivel terreno) → modificar aquí
A9: Altura a la cumbrera | B9: h_c | C9: 8.85 | D9: m | E9: Altura a la cumbrera (desde nivel terreno) → modificar aquí
A10: N° de aguas (techo) | B10: N°ag | C10: 2 | D10: — | E10: 1 = 1 agua (un faldeo) | 2 = 2 aguas (dos faldeos) → selector activo aquí
A11: Altura media del techo | B11: h | C11: =(C8+C9)/2 -> 8.19 | D11: m | E11: §5.8 - h = (h_e + h_c)/2 → calculado
A12: Pendiente cubierta | B12: θ | C12: =DEGREES(ATAN((C9-C8)/(C7/2))) -> 3.0224106 | D12: ° | E12: θ = atan((h_c − h_e) / (B/2)) → calculado
A13: Relación h/L (viento ∥ cumbrera) | B13: h/L | C13: =C11/C6 -> 0.098083832 | D13: — | E13: Para definir zonas Cp del techo → calculado
A14: Relación h/B (viento ⊥ cumbrera) | B14: h/B | C14: =C11/C7 -> 0.1638 | D14: — | E14: Para definir Cp en muros laterales → calculado
A16: 2. PARÁMETROS DE VIENTO (NCh432:2025)
A17: Parámetro | B17: Símbolo | C17: Valor | D17: Unidad | E17: Referencia / Notas
A18: Velocidad básica del viento | B18: V | C18: 34 | D18: m/s | E18: Tabla 1 - Zona III-A (29°54'S - 37°28'S, < 1000 msnm)
A19: Categoría de ocupación | B19: Cat | C19: II | D19: — | E19: NCh3171 - Edificio común
A20: Factor de importancia | B20: I | C20: 1 | D20: — | E20: Tabla 2 - Categoría II → T = 50 años
A21: Factor de direccionalidad | B21: Kd | C21: 0.85 | D21: — | E21: Tabla 3 - Edificios SPRFV
A22: Factor topográfico | B22: Kzt | C22: 1 | D22: — | E22: §5.6 - Sitio plano
A23: Factor elevación del suelo | B23: Ke | C23: 1 | D23: — | E23: §5.7 - Conservador (z_e < 300 msnm)
A24: Factor efecto de ráfaga | B24: G | C24: 0.85 | D24: — | E24: §5.9 - Estructura rígida (f ≥ 1 Hz)
A25: Categoría de exposición | B25: Exp | C25: B | D25: — | E25: §5.5 - B=Urbano, C=Campo abierto, D=Costa
A26: Cerramiento | B26: Cerr | C26: Cerrado | D26: — | E26: §5.10 - Tabla 7: GCpi = ±0,18
A28: 3. CONSTANTES DE EXPOSICIÓN (Tabla 6 NCh432:2025)
A29: Exposición | B29: α | C29: z_g (m) | D29: z_min (m) | E29: Descripción
A30: B | B30: 7.5 | C30: 1000 | D30: 10 | E30: Urbano / suburbano / bosques
A31: C | B31: 9.8 | C31: 750 | D31: 5 | E31: Campo abierto, terrenos con obstrucciones dispersas
A32: D | B32: 11.5 | C32: 590 | D32: 2 | E32: Costa, planos sin obstáculos, frente a masas de agua
A33: α (seleccionado) | B33: α | C33: =IF(C25="B",B30,IF(C25="C",B31,IF(C25="D",B32,""))) -> 7.5 | D33: — | E33: Tabla 6 - Selección automática
A34: z_g (seleccionado) | B34: z_g | C34: =IF(C25="B",C30,IF(C25="C",C31,IF(C25="D",C32,""))) -> 1000 | D34: m | E34: Altura gradiente
A35: z_min (seleccionado) | B35: z_min | C35: =IF(C25="B",D30,IF(C25="C",D31,IF(C25="D",D32,""))) -> 10 | D35: m | E35: Altura mínima
A37: 4. PRESIÓN DE VELOCIDAD qh A LA ALTURA MEDIA DEL TECHO (§5.8)
A38: Parámetro | B38: Símbolo | C38: Valor | D38: Unidad | E38: Referencia / Notas
A39: Coef. exposición a la altura h | B39: Kh | C39: =2.41*(MAX(C11,C35)/C34)^(2/C33) -> 0.70580334 | D39: — | E39: Kh = 2,41·(max(h,z_min)/z_g)^(2/α)
A40: Presión de velocidad a altura h | B40: qh | C40: =0.613*C20*C39*C22*C23*C18^2 -> 500.15201 | D40: N/m² | E40: qh = 0,613·I·Kh·Kzt·Ke·V² (Ec. 5.8.2)
A41: Presión de velocidad a altura h | B41: qh | C41: =C40/9.80665 -> 51.001311 | D41: kgf/m² | E41: Conversión: 1 kgf = 9,80665 N
A43: NOTA: La presión de velocidad qz para muros de barlovento se calcula en la Hoja 2, ya que varía con la altura z. El resto de superficies (sotavento, laterales, techo) usa qh constante.

Sheet Presiones vs Altura
A1: PRESIONES DE VIENTO vs ALTURA - NCh432:2025
A2: qz varía con la altura z; resto de superficies usa qh constante a la altura media del techo
A4: PARÁMETROS (vinculados desde Presión de Viento)
A5: h cumbrera (h_c) | B5: ='Presión de Viento'!C9 -> 8.85 | C5: m ← última fila de la tabla
A6: h alero (h_e) | B6: ='Presión de Viento'!C8 -> 7.53 | C6: m ← fila naranja en tabla
A7: V (velocidad básica) | B7: ='Presión de Viento'!C18 -> 34 | C7: m/s
A8: I / Kd / Kzt / Ke / G | B8: ='Presión de Viento'!C20 -> 1 | C8: ='Presión de Viento'!C21 -> 0.85 | D8: ='Presión de Viento'!C22 -> 1 | E8: ='Presión de Viento'!C23 -> 1 | F8: ='Presión de Viento'!C24 -> 0.85
A9: α / z_g / z_min (Exp. selec.) | B9: ='Presión de Viento'!C33 -> 7.5 | C9: ='Presión de Viento'!C34 -> 1000 | D9: ='Presión de Viento'!C35 -> 10
A10: qh a altura media | B10: ='Presión de Viento'!C41 -> 51.001311 | C10: kgf/m² (constante, para sotavento/laterales/techo)
A11: Cp barlovento muro | B11: ='Resumen Cp'!C17 -> 0.8
A12: ⚠️ NOTA: Los valores de la tabla se calcularon con los parámetros actuales. Si cambias V, Exposición u otros parámetros en la hoja “Presión de Viento”, regenera esta tabla.
A13: Cp muro lateral | B13: ='Resumen Cp'!C19 -> -0.7
A15: z (m) | B15: Kz | C15: qz (kgf/m²) | E15: z (m) | F15: qz
A16: =IF((ROW()-16)*0.1>'Presión de Viento'!$C$9,"",(ROW()-16)*0.1) -> 0 | B16: =IF(A16="","",2.41*(MAX(A16,'Presión de Viento'!$C$35)/'Presión de Viento'!$C$34)^(2/'Presión de Viento'!$C$33)) -> 0.70580334 | C16: =IF(A16="","",0.613*'Presión de Viento'!$C$20*B16*'Presión de Viento'!$C$22*'Presión de Viento'!$C$23*'Presión de Viento'!$C$18^2/9.80665) -> 51.001311 | E16: 0.0 m | F16: =IF(A16="",0,C16) -> 51.001311
A17: =IF((ROW()-16)*0.1>'Presión de Viento'!$C$9,"",(ROW()-16)*0.1) -> 0.1 | B17: =IF(A17="","",2.41*(MAX(A17,'Presión de Viento'!$C$35)/'Presión de Viento'!$C$34)^(2/'Presión de Viento'!$C$33)) -> 0.70580334 | C17: =IF(A17="","",0.613*'Presión de Viento'!$C$20*B17*'Presión de Viento'!$C$22*'Presión de Viento'!$C$23*'Presión de Viento'!$C$18^2/9.80665) -> 51.001311 | E17: 0.1 m | F17: =IF(A17="",0,C17) -> 51.001311
A18: =IF((ROW()-16)*0.1>'Presión de Viento'!$C$9,"",(ROW()-16)*0.1) -> 0.2 | B18: =IF(A18="","",2.41*(MAX(A18,'Presión de Viento'!$C$35)/'Presión de Viento'!$C$34)^(2/'Presión de Viento'!$C$33)) -> 0.70580334 | C18: =IF(A18="","",0.613*'Presión de Viento'!$C$20*B18*'Presión de Viento'!$C$22*'Presión de Viento'!$C$23*'Presión de Viento'!$C$18^2/9.80665) -> 51.001311 | E18: 0.2 m | F18: =IF(A18="",0,C18) -> 51.001311
A19: =IF((ROW()-16)*0.1>'Presión de Viento'!$C$9,"",(ROW()-16)*0.1) -> 0.3 | B19: =IF(A19="","",2.41*(MAX(A19,'Presión de Viento'!$C$35)/'Presión de Viento'!$C$34)^(2/'Presión de Viento'!$C$33)) -> 0.70580334 | C19: =IF(A19="","",0.613*'Presión de Viento'!$C$20*B19*'Presión de Viento'!$C$22*'Presión de Viento'!$C$23*'Presión de Viento'!$C$18^2/9.80665) -> 51.001311 | E19: 0.3 m | F19: =IF(A19="",0,C19) -> 51.001311
A20: =IF((ROW()-16)*0.1>'Presión de Viento'!$C$9,"",(ROW()-16)*0.1) -> 0.4 | B20: =IF(A20="","",2.41*(MAX(A20,'Presión de Viento'!$C$35)/'Presión de Viento'!$C$34)^(2/'Presión de Viento'!$C$33)) -> 0.70580334 | C20: =IF(A20="","",0.613*'Presión de Viento'!$C$20*B20*'Presión de Viento'!$C$22*'Presión de Viento'!$C$23*'Presión de Viento'!$C$18^2/9.80665) -> 51.001311 | E20: 0.4 m | F20: =IF(A20="",0,C20) -> 51.001311
A21: =IF((ROW()-16)*0.1>'Presión de Viento'!$C$9,"",(ROW()-16)*0.1) -> 0.5 | B21: =IF(A21="","",2.41*(MAX(A21,'Presión de Viento'!$C$35)/'Presión de Viento'!$C$34)^(2/'Presión de Viento'!$C$33)) -> 0.70580334 | C21: =IF(A21="","",0.613*'Presión de Viento'!$C$20*B21*'Presión de Viento'!$C$22*'Presión de Viento'!$C$23*'Presión de Viento'!$C$18^2/9.80665) -> 51.001311 | E21: 0.5 m | F21: =IF(A21="",0,C21) -> 51.001311
A22: =IF((ROW()-16)*0.1>'Presión de Viento'!$C$9,"",(ROW()-16)*0.1) -> 0.6 | B22: =IF(A22="","",2.41*(MAX(A22,'Presión de Viento'!$C$35)/'Presión de Viento'!$C$34)^(2/'Presión de Viento'!$C$33)) -> 0.70580334 | C22: =IF(A22="","",0.613*'Presión de Viento'!$C$20*B22*'Presión de Viento'!$C$22*'Presión de Viento'!$C$23*'Presión de Viento'!$C$18^2/9.80665) -> 51.001311 | E22: 0.6 m | F22: =IF(A22="",0,C22) -> 51.001311
A23: =IF((ROW()-16)*0.1>'Presión de Viento'!$C$9,"",(ROW()-16)*0.1) -> 0.7 | B23: =IF(A23="","",2.41*(MAX(A23,'Presión de Viento'!$C$35)/'Presión de Viento'!$C$34)^(2/'Presión de Viento'!$C$33)) -> 0.70580334 | C23: =IF(A23="","",0.613*'Presión de Viento'!$C$20*B23*'Presión de Viento'!$C$22*'Presión de Viento'!$C$23*'Presión de Viento'!$C$18^2/9.80665) -> 51.001311 | E23: 0.7 m | F23: =IF(A23="",0,C23) -> 51.001311
A24: =IF((ROW()-16)*0.1>'Presión de Viento'!$C$9,"",(ROW()-16)*0.1) -> 0.8 | B24: =IF(A24="","",2.41*(MAX(A24,'Presión de Viento'!$C$35)/'Presión de Viento'!$C$34)^(2/'Presión de Viento'!$C$33)) -> 0.70580334 | C24: =IF(A24="","",0.613*'Presión de Viento'!$C$20*B24*'Presión de Viento'!$C$22*'Presión de Viento'!$C$23*'Presión de Viento'!$C$18^2/9.80665) -> 51.001311 | E24: 0.8 m | F24: =IF(A24="",0,C24) -> 51.001311
A25: =IF((ROW()-16)*0.1>'Presión de Viento'!$C$9,"",(ROW()-16)*0.1) -> 0.9 | B25: =IF(A25="","",2.41*(MAX(A25,'Presión de Viento'!$C$35)/'Presión de Viento'!$C$34)^(2/'Presión de Viento'!$C$33)) -> 0.70580334 | C25: =IF(A25="","",0.613*'Presión de Viento'!$C$20*B25*'Presión de Viento'!$C$22*'Presión de Viento'!$C$23*'Presión de Viento'!$C$18^2/9.80665) -> 51.001311 | E25: 0.9 m | F25: =IF(A25="",0,C25) -> 51.001311
A26: =IF((ROW()-16)*0.1>'Presión de Viento'!$C$9,"",(ROW()-16)*0.1) -> 1 | B26: =IF(A26="","",2.41*(MAX(A26,'Presión de Viento'!$C$35)/'Presión de Viento'!$C$34)^(2/'Presión de Viento'!$C$33)) -> 0.70580334 | C26: =IF(A26="","",0.613*'Presión de Viento'!$C$20*B26*'Presión de Viento'!$C$22*'Presión de Viento'!$C$23*'Presión de Viento'!$C$18^2/9.80665) -> 51.001311 | E26: 1.0 m | F26: =IF(A26="",0,C26) -> 51.001311
A27: =IF((ROW()-16)*0.1>'Presión de Viento'!$C$9,"",(ROW()-16)*0.1) -> 1.1 | B27: =IF(A27="","",2.41*(MAX(A27,'Presión de Viento'!$C$35)/'Presión de Viento'!$C$34)^(2/'Presión de Viento'!$C$33)) -> 0.70580334 | C27: =IF(A27="","",0.613*'Presión de Viento'!$C$20*B27*'Presión de Viento'!$C$22*'Presión de Viento'!$C$23*'Presión de Viento'!$C$18^2/9.80665) -> 51.001311 | E27: 1.1 m | F27: =IF(A27="",0,C27) -> 51.001311
... A215: =IF((ROW()-16)*0.1>'Presión de Viento'!$C$9,"",(ROW()-16)*0.1) | B215: =IF(A215="","",2.41*(MAX(A215,'Presión de Viento'!$C$35)/'Presión de Viento'!$C$34)^(2/'Presión de Viento'!$C$33)) | C215: =IF(A215="","",0.613*'Presión de Viento'!$C$20*B215*'Presión de Viento'!$C$22*'Presión de Viento'!$C$23*'Presión de Viento'!$C$18^2/9.80665) | E215: 19.9 m | F215: =IF(A215="",0,C215) -> 0

Sheet Cp - techos
A2: 1. DATOS DE ENTRADA
A3: Entradas | B3: Valores
A4: h cumbrera | B4: ='Resumen Cp'!B4 -> 8.85 | C4: m
A5: h hombro | B5: ='Resumen Cp'!B5 -> 7.53 | C5: m
A6: L | B6: ='Resumen Cp'!B6 -> 83.5 | C6: m
A7: B | B7: ='Resumen Cp'!B7 -> 50 | C7: m | D7: Condición
A8: h | B8: =AVERAGE(B4:B5) -> 8.19 | C8: m | D8: hz=h
A9: Ángulo θ | B9: =DEGREES(ATAN((B4-B5)/(B7/2))) -> 3.0224106 | C9: ° | D9: qz=qh
A12: ANÁLISIS EN DIRECCION PERPENDICULAR A LA CARA CORTA DEL EDIFICIO
A13: 1. CP MUROS
A15: L | B15: =B6 -> 83.5
A16: B | B16: =B7 -> 50
A17: h/L | B17: =B8/B6 -> 0.098083832
A18: L/B | B18: =B6/B7 -> 1.67
A20: Cp Barlovento | B20: 0.8 | C20: usar con qz
A21: Cp Sotavento | B21: =IF(B18<=1, -0.5, IF(B18>=4, -0.2, IF(B18<=2, -0.5+(B18-1)*(-0.3-(-0.5))/(2-1), -0.3+(B18-2)*(-0.2-(-0.3))/(4-2)))) -> -0.366 | C21: usar con qh
A22: Cp Muro Lateral | B22: -0.7 | C22: usar con qh
A25: 3. CP TECHO - BARLOVENTO PARA PENDIENTES MAYORES A 10°
A28: Resultados | B28: Fórmulas
A29: Cp Barlovento Succión (Máx) | B29: {=IF(TRUE,"No Aplica",IF(B9>=80,0.8,IF(B9>60,0.01*B9,IF(B9<10,"Techo Plano",((INDEX(B32:I32,MATCH(B9,B32:I32,1)+1)-B9)/(INDEX(B32:I32,MATCH(B9,B32:I32,1)+1)-INDEX(B32:I32,MATCH(B9,B32:I32,1)))*INDEX(B33:I35,IF(B17<=0.25,1,MATCH(MIN(B17,1),A33:A35,1)),MATCH(B9,B32:I32,1))+(B9-INDEX(B32:I32,MATCH(B9,B32:I32,1)))/(INDEX(B32:I32,MATCH(B9,B32:I32,1)+1)-INDEX(B32:I32,MATCH(B9,B32:I32,1)))*INDEX(B33:I35,IF(B17<=0.25,1,MATCH(MIN(B17,1),A33:A35,1)),MATCH(B9,B32:I32,1)+1))*(IF(B17>=1,1,INDEX(A33:A35,IF(B17<=0.25,1,MATCH(MIN(B17,1),A33:A35,1))+1))-IF(B17<=0.25,0.25,MIN(B17,1)))/(IF(B17>=1,1,INDEX(A33:A35,IF(B17<=0.25,1,MATCH(MIN(B17,1),A33:A35,1))+1))-IF(B17<=0.25,0.25,INDEX(A33:A35,MATCH(MIN(B17,1),A33:A35,1))))+((INDEX(B32:I32,MATCH(B9,B32:I32,1)+1)-B9)/(INDEX(B32:I32,MATCH(B9,B32:I32,1)+1)-INDEX(B32:I32,MATCH(B9,B32:I32,1)))*INDEX(B33:I35,IF(B17>=1,3,IF(B17<=0.25,1,MATCH(MIN(B17,1),A33:A35,1))+1),MATCH(B9,B32:I32,1))+(B9-INDEX(B32:I32,MATCH(B9,B32:I32,1)))/(INDEX(B32:I32,MATCH(B9,B32:I32,1)+1)-INDEX(B32:I32,MATCH(B9,B32:I32,1)))*INDEX(B33:I35,IF(B17>=1,3,IF(B17<=0.25,1,MATCH(MIN(B17,1),A33:A35,1))+1),MATCH(B9,B32:I32,1)+1))*(IF(B17<=0.25,0.25,MIN(B17,1))-IF(B17<=0.25,0.25,INDEX(A33:A35,MATCH(MIN(B17,1),A33:A35,1))))/(IF(B17>=1,1,INDEX(A33:A35,IF(B17<=0.25,1,MATCH(MIN(B17,1),A33:A35,1))+1))-IF(B17<=0.25,0.25,INDEX(A33:A35,MATCH(MIN(B17,1),A33:A35,1))))))))} -> No Aplica
A30: Cp Barlovento Presión (Máx) | B30: {=IF(TRUE,"No Aplica",IF(B9>=80,0.8,IF(B9>60,0.01*B9,IF(B9<10,"Techo Plano",((INDEX(B37:I37,MATCH(B9,B37:I37,1)+1)-B9)/(INDEX(B37:I37,MATCH(B9,B37:I37,1)+1)-INDEX(B37:I37,MATCH(B9,B37:I37,1)))*INDEX(B38:I40,IF(B17<=0.25,1,MATCH(MIN(B17,1),A38:A40,1)),MATCH(B9,B37:I37,1))+(B9-INDEX(B37:I37,MATCH(B9,B37:I37,1)))/(INDEX(B37:I37,MATCH(B9,B37:I37,1)+1)-INDEX(B37:I37,MATCH(B9,B37:I37,1)))*INDEX(B38:I40,IF(B17<=0.25,1,MATCH(MIN(B17,1),A38:A40,1)),MATCH(B9,B37:I37,1)+1))*(IF(B17>=1,1,INDEX(A38:A40,IF(B17<=0.25,1,MATCH(MIN(B17,1),A38:A40,1))+1))-IF(B17<=0.25,0.25,MIN(B17,1)))/(IF(B17>=1,1,INDEX(A38:A40,IF(B17<=0.25,1,MATCH(MIN(B17,1),A38:A40,1))+1))-IF(B17<=0.25,0.25,INDEX(A38:A40,MATCH(MIN(B17,1),A38:A40,1))))+((INDEX(B37:I37,MATCH(B9,B37:I37,1)+1)-B9)/(INDEX(B37:I37,MATCH(B9,B37:I37,1)+1)-INDEX(B37:I37,MATCH(B9,B37:I37,1)))*INDEX(B38:I40,IF(B17>=1,3,IF(B17<=0.25,1,MATCH(MIN(B17,1),A38:A40,1))+1),MATCH(B9,B37:I37,1))+(B9-INDEX(B37:I37,MATCH(B9,B37:I37,1)))/(INDEX(B37:I37,MATCH(B9,B37:I37,1)+1)-INDEX(B37:I37,MATCH(B9,B37:I37,1)))*INDEX(B38:I40,IF(B17>=1,3,IF(B17<=0.25,1,MATCH(MIN(B17,1),A38:A40,1))+1),MATCH(B9,B37:I37,1)+1))*(IF(B17<=0.25,0.25,MIN(B17,1))-IF(B17<=0.25,0.25,INDEX(A38:A40,MATCH(MIN(B17,1),A38:A40,1))))/(IF(B17>=1,1,INDEX(A38:A40,IF(B17<=0.25,1,MATCH(MIN(B17,1),A38:A40,1))+1))-IF(B17<=0.25,0.25,INDEX(A38:A40,MATCH(MIN(B17,1),A38:A40,1))))))))} -> No Aplica
A32: h/L | B32: 10 | C32: 15 | D32: 20 | E32: 25 | F32: 30 | G32: 35 | H32: 45 | I32: 60
A33: 0.25 | B33: -0.7 | C33: -0.5 | D33: -0.3 | E33: -0.2 | F33: -0.2 | G33: 0 | H33: 0 | I33: 0.6
A34: 0.5 | B34: -0.9 | C34: -0.7 | D34: -0.4 | E34: -0.3 | F34: -0.2 | G34: -0.2 | H34: 0 | I34: 0.6
A35: 1 | B35: -1.3 | C35: -1 | D35: -0.7 | E35: -0.5 | F35: -0.3 | G35: -0.2 | H35: 0 | I35: 0.6
A37: h/L | B37: 10 | C37: 15 | D37: 20 | E37: 25 | F37: 30 | G37: 35 | H37: 45 | I37: 60
A38: 0.25 | B38: -0.18 | C38: 0 | D38: 0.2 | E38: 0.3 | F38: 0.3 | G38: 0.4 | H38: 0.4 | I38: 0.6
A39: 0.5 | B39: -0.18 | C39: -0.18 | D39: 0 | E39: 0.2 | F39: 0.2 | G39: 0.3 | H39: 0.4 | I39: 0.6
A40: 1 | B40: -0.18 | C40: -0.18 | D40: -0.18 | E40: 0 | F40: 0.2 | G40: 0.2 | H40: 0.3 | I40: 0.6
A43: 4. CP TECHO - SOTAVENTO PARA PENDIENTES MAYORES A 10°
A45: Entradas | B45: Valores | D45: Auxiliares | E45: Fórmulas
A46: h/L | B46: =B17 -> 0.098083832 | D46: h/L acotado | E46: {=IF(TRUE,"No Aplica",IF(B9<10,"Techo Plano",((INDEX(B51:D53,MAX(1,IFERROR(MATCH(MAX(0.25,MIN(1,B46)),A51:A53,1),1)),MAX(1,MATCH(B47,B50:D50,1)))+IF(INDEX(B50:D50,1,MIN(3,MAX(1,MATCH(B47,B50:D50,1))+1))<>INDEX(B50:D50,1,MAX(1,MATCH(B47,B50:D50,1))),(B47-INDEX(B50:D50,1,MAX(1,MATCH(B47,B50:D50,1))))/(INDEX(B50:D50,1,MIN(3,MAX(1,MATCH(B47,B50:D50,1))+1))-INDEX(B50:D50,1,MAX(1,MATCH(B47,B50:D50,1)))),0)*(INDEX(B51:D53,MAX(1,IFERROR(MATCH(MAX(0.25,MIN(1,B46)),A51:A53,1),1)),MIN(3,MAX(1,MATCH(B47,B50:D50,1))+1))-INDEX(B51:D53,MAX(1,IFERROR(MATCH(MAX(0.25,MIN(1,B46)),A51:A53,1),1)),MAX(1,MATCH(B47,B50:D50,1)))))+IF(INDEX(A51:A53,MIN(3,MAX(1,IFERROR(MATCH(MAX(0.25,MIN(1,B46)),A51:A53,1),1))+1))<>INDEX(A51:A53,MAX(1,IFERROR(MATCH(MAX(0.25,MIN(1,B46)),A51:A53,1),1))),(MAX(0.25,MIN(1,B46))-INDEX(A51:A53,MAX(1,IFERROR(MATCH(MAX(0.25,MIN(1,B46)),A51:A53,1),1))))/(INDEX(A51:A53,MIN(3,MAX(1,IFERROR(MATCH(MAX(0.25,MIN(1,B46)),A51:A53,1),1))+1))-INDEX(A51:A53,MAX(1,IFERROR(MATCH(MAX(0.25,MIN(1,B46)),A51:A53,1),1)))),0)*((INDEX(B51:D53,MIN(3,MAX(1,IFERROR(MATCH(MAX(0.25,MIN(1,B46)),A51:A53,1),1))+1),MAX(1,MATCH(B47,B50:D50,1)))+IF(INDEX(B50:D50,1,MIN(3,MAX(1,MATCH(B47,B50:D50,1))+1))<>INDEX(B50:D50,1,MAX(1,MATCH(B47,B50:D50,1))),(B47-INDEX(B50:D50,1,MAX(1,MATCH(B47,B50:D50,1))))/(INDEX(B50:D50,1,MIN(3,MAX(1,MATCH(B47,B50:D50,1))+1))-INDEX(B50:D50,1,MAX(1,MATCH(B47,B50:D50,1)))),0)*(INDEX(B51:D53,MIN(3,MAX(1,IFERROR(MATCH(MAX(0.25,MIN(1,B46)),A51:A53,1),1))+1),MIN(3,MAX(1,MATCH(B47,B50:D50,1))+1))-INDEX(B51:D53,MIN(3,MAX(1,IFERROR(MATCH(MAX(0.25,MIN(1,B46)),A51:A53,1),1))+1),MAX(1,MATCH(B47,B50:D50,1)))))-(INDEX(B51:D53,MAX(1,IFERROR(MATCH(MAX(0.25,MIN(1,B46)),A51:A53,1),1)),MAX(1,MATCH(B47,B50:D50,1)))+IF(INDEX(B50:D50,1,MIN(3,MAX(1,MATCH(B47,B50:D50,1))+1))<>INDEX(B50:D50,1,MAX(1,MATCH(B47,B50:D50,1))),(B47-INDEX(B50:D50,1,MAX(1,MATCH(B47,B50:D50,1))))/(INDEX(B50:D50,1,MIN(3,MAX(1,MATCH(B47,B50:D50,1))+1))-INDEX(B50:D50,1,MAX(1,MATCH(B47,B50:D50,1)))),0)*(INDEX(B51:D53,MAX(1,IFERROR(MATCH(MAX(0.25,MIN(1,B46)),A51:A53,1),1)),MIN(3,MAX(1,MATCH(B47,B50:D50,1))+1))-INDEX(B51:D53,MAX(1,IFERROR(MATCH(MAX(0.25,MIN(1,B46)),A51:A53,1),1)),MAX(1,MATCH(B47,B50:D50,1)))))))))} -> No Aplica
A47: Ángulo θ | B47: =B9 -> 3.0224106
A50: h/L | B50: 10 | C50: 15 | D50: 20
A51: 0.25 | B51: -0.3 | C51: -0.5 | D51: -0.6
A52: 0.5 | B52: -0.5 | C52: -0.5 | D52: -0.6
A53: 1 | B53: -0.7 | C53: -0.6 | D53: -0.6
A57: 5. CP TECHO - TECHOS PLANOS MENORES A 10°
A59: Entradas | B59: Valores | F59: Factor por Área
A60: h (Altura media) | B60: =B8 -> 8.19 | F60: Área zona (m²) | G60: =('Resumen Cp'!B6*'Resumen Cp'!B7/2)/COS(RADIANS(B9))*'Resumen Cp'!B8 -> 4180.8156 | H60: (L × B/2 × N°aguas) / cos(θ)
...

Sheet Resumen Cp
A1: RESUMEN COEFICIENTES DE PRESIÓN - Cp
A3: DATOS DE ENTRADA | B3: Valor | C3: Unidad
A4: h cumbrera | B4: ='Presión de Viento'!C9 -> 8.85 | C4: m
A5: h hombro | B5: ='Presión de Viento'!C8 -> 7.53 | C5: m
A6: L (largo) | B6: ='Presión de Viento'!C6 -> 83.5 | C6: m
A7: B (ancho) | B7: ='Presión de Viento'!C7 -> 50 | C7: m
A8: N° de aguas | B8: ='Presión de Viento'!C10 -> 2 | C8: aguas
A9: h (altura media) | B9: =AVERAGE(B4,B5) -> 8.19 | C9: m
A10: Ángulo θ | B10: =DEGREES(ATAN((B4-B5)/(B7/2))) -> 3.0224106 | C10: °
A11: Tipo de techo | B11: =IF(B10<10, IF(B8=1,"Techo plano - 1 agua (θ < 10°)","Techo plano - 2 aguas (θ < 10°)"), IF(B8=1,"Techo 1 agua (θ ≥ 10°)","Techo a dos aguas (θ ≥ 10°)")) -> Techo plano - 2 aguas (θ < 10°)
A14: Superficie | B14: Usar con | C14: Perpendicular cara CORTA | E14: Perpendicular cara LARGA
C15: Cp | D15: L/B | E15: Cp | F15: L/B
A16: CP MUROS
A17: Barlovento | B17: qz | C17: ='Cp - techos'!B82 -> 0.8 | D17: ='Cp - techos'!B18 -> 1.67 | E17: ='Cp - techos'!B166 -> 0.8 | F17: ='Cp - techos'!B102 -> 0.5988024
A18: Sotavento | B18: qh | C18: ='Cp - techos'!B83 -> -0.366 | D18: ='Cp - techos'!B18 -> 1.67 | E18: ='Cp - techos'!B167 -> -0.5 | F18: ='Cp - techos'!B102 -> 0.5988024
A19: Muro Lateral | B19: qh | C19: ='Cp - techos'!B84 -> -0.7 | D19: — | E19: ='Cp - techos'!B168 -> -0.7 | F19: —
A21: CP TECHO (pendientes > 10°) | C21: Perpendicular cara CORTA | E21: Perpendicular cara LARGA
A22: Barlovento (Succión Máx) | B22: qh | C22: ='Cp - techos'!B87 -> No Aplica | D22: — | E22: No Aplica | F22: —
A23: Barlovento (Presión Máx) | B23: qh | C23: ='Cp - techos'!C87 -> No Aplica | D23: — | E23: No Aplica | F23: —
A24: Sotavento | B24: qh | C24: ='Cp - techos'!B88 -> No Aplica | D24: — | E24: No Aplica | F24: —
A26: CP TECHO PLANO / NORMAL A CUMBRERA | C26: Perpendicular cara CORTA | E26: Perpendicular cara LARGA
A27: Zona | B27: qh | C27: Cp Caso 1 | D27: Cp Caso 2 | E27: Cp Caso 1 | F27: Cp Caso 2
A28: 1 (0 a h/2) | B28: qh | C28: ='Cp - techos'!D91 -> -0.9 | D28: ='Cp - techos'!E91 -> -0.18 | E28: ='Cp - techos'!D175 -> -0.9 | F28: ='Cp - techos'!E175 -> -0.18
A29: 2 (h/2 a h) | B29: qh | C29: ='Cp - techos'!D92 -> -0.9 | D29: ='Cp - techos'!E92 -> -0.18 | E29: ='Cp - techos'!D176 -> -0.9 | F29: ='Cp - techos'!E176 -> -0.18
A30: 3 (h a 2h) | B30: qh | C30: ='Cp - techos'!D93 -> -0.5 | D30: ='Cp - techos'!E93 -> -0.18 | E30: ='Cp - techos'!D177 -> -0.5 | F30: ='Cp - techos'!E177 -> -0.18
A31: 4 (> 2h) | B31: qh | C31: ='Cp - techos'!D94 -> -0.3 | D31: ='Cp - techos'!E94 -> -0.18 | E31: ='Cp - techos'!D178 -> -0.3 | F31: ='Cp - techos'!E178 -> -0.18

Sheet SPRFV - Cara Corta
A1: PRESIONES DE DISEÑO SPRFV - VALORES PARA SAP2000 [kgf/m²]
A2: Ecuación: p = q·Kd·G·Cp − qh·Kd·(GCpi) (NCh432:2025 Ec. 4)
A3: PARÁMETROS | B3: Valor | C3: Unidad
A4: qz (altura z) | B4: =0.613*'Presión de Viento'!C20*(2.41*(MAX('Presión de Viento'!C9,'Presión de Viento'!C35)/'Presión de Viento'!C34)^(2/'Presión de Viento'!C33))*'Presión de Viento'!C22*'Presión de Viento'!C23*'Presión de Viento'!C18^2/9.80665 -> 51.001311 | C4: kgf/m²
A5: qh (altura h media) | B5: ='Presión de Viento'!C41 -> 51.001311 | C5: kgf/m²
A6: qi (interna, = qh) | B6: =B5 -> 51.001311 | C6: kgf/m²
A7: Kd | B7: ='Presión de Viento'!C21 -> 0.85 | C7: —
A8: G | B8: ='Presión de Viento'!C24 -> 0.85 | C8: —
A10: CASO A: VIENTO ⊥ CUMBRERA (sobre B = 50 m) + Presión Interna POSITIVA (+0,18)
A11: Superficie | B11: Cp | C11: GCpi | D11: q usado | E11: Cp·G | F11: p externa (kgf/m²) | G11: p interna (kgf/m²) | H11: p NETA (kgf/m²)
A12: Muro barlovento | B12: ='Resumen Cp'!C17 -> 0.8 | C12: 0.18 | D12: qz | E12: =B12*$B$8 -> 0.68 | F12: =$B$4*$B$7*$B$8*B12 -> 29.478758 | G12: =$B$6*$B$7*C12 -> 7.8032006 | H12: =F12-G12 -> 21.675557
A13: Muro de sotavento | B13: ='Resumen Cp'!C18 -> -0.366 | C13: 0.18 | D13: qh | E13: =B13*$B$8 -> -0.3111 | F13: =$B$5*$B$7*$B$8*B13 -> -13.486532 | G13: =$B$6*$B$7*C13 -> 7.8032006 | H13: =F13-G13 -> -21.289732
A14: Muros laterales | B14: ='Resumen Cp'!C19 -> -0.7 | C14: 0.18 | D14: qh | E14: =B14*$B$8 -> -0.595 | F14: =$B$5*$B$7*$B$8*B14 -> -25.793913 | G14: =$B$6*$B$7*C14 -> 7.8032006 | H14: =F14-G14 -> -33.597114
A15: Techo zona 1 (0 a h/2) | B15: ='Resumen Cp'!C28 -> -0.9 | C15: 0.18 | D15: qh | E15: =B15*$B$8 -> -0.765 | F15: =$B$5*$B$7*$B$8*B15 -> -33.163603 | G15: =$B$6*$B$7*C15 -> 7.8032006 | H15: =F15-G15 -> -40.966803
A16: Techo zona 2 (h/2 a h) | B16: ='Resumen Cp'!C29 -> -0.9 | C16: 0.18 | D16: qh | E16: =B16*$B$8 -> -0.765 | F16: =$B$5*$B$7*$B$8*B16 -> -33.163603 | G16: =$B$6*$B$7*C16 -> 7.8032006 | H16: =F16-G16 -> -40.966803
A17: Techo zona 3 (h a 2h) | B17: ='Resumen Cp'!C30 -> -0.5 | C17: 0.18 | D17: qh | E17: =B17*$B$8 -> -0.425 | F17: =$B$5*$B$7*$B$8*B17 -> -18.424224 | G17: =$B$6*$B$7*C17 -> 7.8032006 | H17: =F17-G17 -> -26.227424
A18: Techo zona 4 (> 2h) | B18: ='Resumen Cp'!C31 -> -0.3 | C18: 0.18 | D18: qh | E18: =B18*$B$8 -> -0.255 | F18: =$B$5*$B$7*$B$8*B18 -> -11.054534 | G18: =$B$6*$B$7*C18 -> 7.8032006 | H18: =F18-G18 -> -18.857735
A20: CASO B: VIENTO ⊥ CUMBRERA (sobre B = 50 m) + Presión Interna NEGATIVA (−0,18)
A21: Superficie | B21: Cp | C21: GCpi | D21: q usado | E21: Cp·G | F21: p externa (kgf/m²) | G21: p interna (kgf/m²) | H21: p NETA (kgf/m²)
A22: Muro barlovento | B22: =B12 -> 0.8 | C22: -0.18 | D22: qz | E22: =B22*$B$8 -> 0.68 | F22: =$B$4*$B$7*$B$8*B22 -> 29.478758 | G22: =$B$6*$B$7*C22 -> -7.8032006 | H22: =F22-G22 -> 37.281959
A23: Muro de sotavento | B23: =B13 -> -0.366 | C23: -0.18 | D23: qh | E23: =B23*$B$8 -> -0.3111 | F23: =$B$5*$B$7*$B$8*B23 -> -13.486532 | G23: =$B$6*$B$7*C23 -> -7.8032006 | H23: =F23-G23 -> -5.6833311
A24: Muros laterales | B24: =B14 -> -0.7 | C24: -0.18 | D24: qh | E24: =B24*$B$8 -> -0.595 | F24: =$B$5*$B$7*$B$8*B24 -> -25.793913 | G24: =$B$6*$B$7*C24 -> -7.8032006 | H24: =F24-G24 -> -17.990713
A25: Techo zona 1 (0 a h/2) | B25: =B15 -> -0.9 | C25: -0.18 | D25: qh | E25: =B25*$B$8 -> -0.765 | F25: =$B$5*$B$7*$B$8*B25 -> -33.163603 | G25: =$B$6*$B$7*C25 -> -7.8032006 | H25: =F25-G25 -> -25.360402
A26: Techo zona 2 (h/2 a h) | B26: =B16 -> -0.9 | C26: -0.18 | D26: qh | E26: =B26*$B$8 -> -0.765 | F26: =$B$5*$B$7*$B$8*B26 -> -33.163603 | G26: =$B$6*$B$7*C26 -> -7.8032006 | H26: =F26-G26 -> -25.360402
A27: Techo zona 3 (h a 2h) | B27: =B17 -> -0.5 | C27: -0.18 | D27: qh | E27: =B27*$B$8 -> -0.425 | F27: =$B$5*$B$7*$B$8*B27 -> -18.424224 | G27: =$B$6*$B$7*C27 -> -7.8032006 | H27: =F27-G27 -> -10.621023
A28: Techo zona 4 (> 2h) | B28: =B18 -> -0.3 | C28: -0.18 | D28: qh | E28: =B28*$B$8 -> -0.255 | F28: =$B$5*$B$7*$B$8*B28 -> -11.054534 | G28: =$B$6*$B$7*C28 -> -7.8032006 | H28: =F28-G28 -> -3.2513336
A30: CONVENCIÓN DE SIGNOS: Valores POSITIVOS = presión hacia la superficie (empuje hacia adentro). Valores NEGATIVOS = succión (alejándose de la superficie). Para SAP2000, aplicar las presiones como cargas distribuidas perpendiculares a cada superficie con el signo indicado.

Sheet SPRFV - Cara Larga
A1: PRESIONES DE DISEÑO SPRFV - VALORES PARA SAP2000 [kgf/m²]
A2: Ecuación: p = q·Kd·G·Cp − qh·Kd·(GCpi) (NCh432:2025 Ec. 4)
A3: PARÁMETROS | B3: Valor | C3: Unidad
A4: qz (altura z) | B4: ='SPRFV - Cara Corta'!$B$4 -> 51.001311 | C4: kgf/m²
A5: qh (altura h media) | B5: ='SPRFV - Cara Corta'!$B$5 -> 51.001311 | C5: kgf/m²
A6: qi (interna, = qh) | B6: ='SPRFV - Cara Corta'!$B$6 -> 51.001311 | C6: kgf/m²
A7: Kd | B7: ='SPRFV - Cara Corta'!$B$7 -> 0.85 | C7: —
A8: G | B8: ='SPRFV - Cara Corta'!$B$8 -> 0.85 | C8: —
A10: CASO A: VIENTO ⊥ CARA LARGA (sobre L = 85 m) + Presión Interna POSITIVA (+0,18)
A11: Superficie | B11: Cp | C11: GCpi | D11: q usado | E11: Cp·G | F11: p externa (kgf/m²) | G11: p interna (kgf/m²) | H11: p NETA (kgf/m²)
A12: Muro barlovento | B12: ='Resumen Cp'!E17 -> 0.8 | C12: 0.18 | D12: qz | E12: =B12*$B$8 -> 0.68 | F12: =$B$4*$B$7*$B$8*B12 -> 29.478758 | G12: =$B$6*$B$7*C12 -> 7.8032006 | H12: =F12-G12 -> 21.675557
A13: Muro de sotavento | B13: ='Resumen Cp'!E18 -> -0.5 | C13: 0.18 | D13: qh | E13: =B13*$B$8 -> -0.425 | F13: =$B$5*$B$7*$B$8*B13 -> -18.424224 | G13: =$B$6*$B$7*C13 -> 7.8032006 | H13: =F13-G13 -> -26.227424
A14: Muros laterales | B14: ='Resumen Cp'!E19 -> -0.7 | C14: 0.18 | D14: qh | E14: =B14*$B$8 -> -0.595 | F14: =$B$5*$B$7*$B$8*B14 -> -25.793913 | G14: =$B$6*$B$7*C14 -> 7.8032006 | H14: =F14-G14 -> -33.597114
A15: Techo zona 1 (0 a h/2) | B15: ='Resumen Cp'!E28 -> -0.9 | C15: 0.18 | D15: qh | E15: =B15*$B$8 -> -0.765 | F15: =$B$5*$B$7*$B$8*B15 -> -33.163603 | G15: =$B$6*$B$7*C15 -> 7.8032006 | H15: =F15-G15 -> -40.966803
A16: Techo zona 2 (h/2 a h) | B16: ='Resumen Cp'!E29 -> -0.9 | C16: 0.18 | D16: qh | E16: =B16*$B$8 -> -0.765 | F16: =$B$5*$B$7*$B$8*B16 -> -33.163603 | G16: =$B$6*$B$7*C16 -> 7.8032006 | H16: =F16-G16 -> -40.966803
A17: Techo zona 3 (h a 2h) | B17: ='Resumen Cp'!E30 -> -0.5 | C17: 0.18 | D17: qh | E17: =B17*$B$8 -> -0.425 | F17: =$B$5*$B$7*$B$8*B17 -> -18.424224 | G17: =$B$6*$B$7*C17 -> 7.8032006 | H17: =F17-G17 -> -26.227424
A18: Techo zona 4 (> 2h) | B18: ='Resumen Cp'!E31 -> -0.3 | C18: 0.18 | D18: qh | E18: =B18*$B$8 -> -0.255 | F18: =$B$5*$B$7*$B$8*B18 -> -11.054534 | G18: =$B$6*$B$7*C18 -> 7.8032006 | H18: =F18-G18 -> -18.857735
A20: CASO B: VIENTO ⊥ CARA LARGA (sobre L = 85 m) + Presión Interna NEGATIVA (−0,18)
A21: Superficie | B21: Cp | C21: GCpi | D21: q usado | E21: Cp·G | F21: p externa (kgf/m²) | G21: p interna (kgf/m²) | H21: p NETA (kgf/m²)
A22: Muro barlovento | B22: =B12 -> 0.8 | C22: -0.18 | D22: qz | E22: =B22*$B$8 -> 0.68 | F22: =$B$4*$B$7*$B$8*B22 -> 29.478758 | G22: =$B$6*$B$7*C22 -> -7.8032006 | H22: =F22-G22 -> 37.281959
A23: Muro de sotavento | B23: =B13 -> -0.5 | C23: -0.18 | D23: qh | E23: =B23*$B$8 -> -0.425 | F23: =$B$5*$B$7*$B$8*B23 -> -18.424224 | G23: =$B$6*$B$7*C23 -> -7.8032006 | H23: =F23-G23 -> -10.621023
A24: Muros laterales | B24: =B14 -> -0.7 | C24: -0.18 | D24: qh | E24: =B24*$B$8 -> -0.595 | F24: =$B$5*$B$7*$B$8*B24 -> -25.793913 | G24: =$B$6*$B$7*C24 -> -7.8032006 | H24: =F24-G24 -> -17.990713
A25: Techo zona 1 (0 a h/2) | B25: =B15 -> -0.9 | C25: -0.18 | D25: qh | E25: =B25*$B$8 -> -0.765 | F25: =$B$5*$B$7*$B$8*B25 -> -33.163603 | G25: =$B$6*$B$7*C25 -> -7.8032006 | H25: =F25-G25 -> -25.360402
A26: Techo zona 2 (h/2 a h) | B26: =B16 -> -0.9 | C26: -0.18 | D26: qh | E26: =B26*$B$8 -> -0.765 | F26: =$B$5*$B$7*$B$8*B26 -> -33.163603 | G26: =$B$6*$B$7*C26 -> -7.8032006 | H26: =F26-G26 -> -25.360402
A27: Techo zona 3 (h a 2h) | B27: =B17 -> -0.5 | C27: -0.18 | D27: qh | E27: =B27*$B$8 -> -0.425 | F27: =$B$5*$B$7*$B$8*B27 -> -18.424224 | G27: =$B$6*$B$7*C27 -> -7.8032006 | H27: =F27-G27 -> -10.621023
A28: Techo zona 4 (> 2h) | B28: =B18 -> -0.3 | C28: -0.18 | D28: qh | E28: =B28*$B$8 -> -0.255 | F28: =$B$5*$B$7*$B$8*B28 -> -11.054534 | G28: =$B$6*$B$7*C28 -> -7.8032006 | H28: =F28-G28 -> -3.2513336
A30: CONVENCIÓN DE SIGNOS: Valores POSITIVOS = presión hacia la superficie (empuje hacia adentro). Valores NEGATIVOS = succión (alejándose de la superficie). Para SAP2000, aplicar las presiones como cargas distribuidas perpendiculares a cada superficie con el signo indicado.

Sheet Fuerzas Totales
A1: FUERZAS TOTALES DE VIENTO - SPRFV - NCh432:2025
A2: F = p · A [kgf] Convención: (+) hacia adentro / compresión, (−) succión / hacia afuera
A4: GEOMETRÍA (desde Presión de Viento)
A5: Parámetro | B5: Símbolo | C5: Valor | D5: Unidad
A6: Largo del galpón (paralelo cumbrera) | B6: L | C6: 83.5 | D6: m
A7: Ancho del galpón (⊥ cumbrera) | B7: B | C7: ='Presión de Viento'!C7 -> 50 | D7: m
A8: Altura al alero | B8: h_e | C8: ='Presión de Viento'!C8 -> 7.53 | D8: m
A9: Altura a la cumbrera | B9: h_c | C9: ='Presión de Viento'!C9 -> 8.85 | D9: m
A10: Altura media del techo | B10: h | C10: ='Presión de Viento'!C11 -> 8.19 | D10: m
A12: ÁREAS TRIBUTARIAS
A13: Superficie | B13: Dimensión | C13: Fórmula | D13: Área (m²)
A14: VIENTO ⊥ CARA CORTA (dir. X)
A15: Muro barlovento / sotavento | B15: h × B | C15: =C10&" × "&C6 -> 8,19 × 83,5 | D15: =C10*C7 -> 409.5
A16: Muros laterales | B16: h × L | C16: =C10&" × "&C7 -> 8,19 × 50 | D16: =C8*C6 -> 628.755
A17: Techo zona 1 (0 a h/2) | B17: L × (h/2) / cosθ | D17: =C6*(C10/2)/COS(RADIANS('Presión de Viento'!C12)) -> 342.40879 | E17: =C10/2*C6 -> 341.9325
A18: Techo zona 2 (h/2 a h) | B18: L × (h/2) / cosθ | D18: =C6*(C10/2)/COS(RADIANS('Presión de Viento'!C12)) -> 342.40879 | E18: =C10/2*C6 -> 341.9325
A19: Techo zona 3 (h a 2h) | B19: L × h / cosθ | D19: =C6*C10/COS(RADIANS('Presión de Viento'!C12)) -> 684.81759 | E19: =C10*C6 -> 683.865
A20: Techo zona 4 (> 2h) | B20: L × MAX(B−2h,0) / cosθ | D20: =C6*MAX(C7-2*C10,0)/COS(RADIANS('Presión de Viento'!C12)) -> 2811.1804 | E20: =C6*(C7-2*C10) -> 2807.27
A21: VIENTO ⊥ CARA LARGA (dir. Y)
A22: Muro barlovento / sotavento | B22: h × L | D22: =C8*C6 -> 628.755
A23: Muros laterales | B23: h × B | D23: =C10*C7 -> 409.5
A24: Techo zona 1 (0 a h/2) | B24: B × (h/2) / cosθ | D24: =C7*(C10/2)/COS(RADIANS('Presión de Viento'!C12)) -> 205.03521 | E24: =C10/2*C7 -> 204.75
A25: Techo zona 2 (h/2 a h) | B25: B × (h/2) / cosθ | D25: =C7*(C10/2)/COS(RADIANS('Presión de Viento'!C12)) -> 205.03521 | E25: =C10/2*C7 -> 204.75
A26: Techo zona 3 (h a 2h) | B26: B × h / cosθ | D26: =C7*C10/COS(RADIANS('Presión de Viento'!C12)) -> 410.07041 | E26: =C10*C7 -> 409.5
A27: Techo zona 4 (> 2h) | B27: B × MAX(L−2h,0) / cosθ | D27: =C7*MAX(C6-2*C10,0)/COS(RADIANS('Presión de Viento'!C12)) -> 3360.6747 | E27: =C7*(C6-2*C10) -> 3356
A29: FUERZAS TOTALES F = p × A
A30: Superficie | B30: Eje global | C30: Área (m²) | D30: CASO A (+GCpi) p NETA (kgf/m²) | E30: CASO A F (kgf) | F30: CASO A F (ton) | G30: CASO B (−GCpi) p NETA (kgf/m²) | H30: CASO B F (kgf) | I30: CASO B F (ton)
A31: VIENTO ⊥ CARA CORTA (dir. X)
A32: Muro barlovento | B32: X (+) | C32: =D15 -> 409.5 | D32: ='SPRFV - Cara Corta'!H12 -> 21.675557 | E32: =D32*C32 -> 8876.1407 | F32: =E32/1000 -> 8.8761407 | G32: ='SPRFV - Cara Corta'!H22 -> 37.281959 | H32: =G32*C32 -> 15266.962 | I32: =H32/1000 -> 15.266962
A33: Muro sotavento | B33: X (+) | C33: =D15 -> 409.5 | D33: =-'SPRFV - Cara Corta'!H13 -> 21.289732 | E33: =D33*C33 -> 8718.1454 | F33: =E33/1000 -> 8.7181454 | G33: =-'SPRFV - Cara Corta'!H23 -> 5.6833311 | H33: =G33*C33 -> 2327.3241 | I33: =H33/1000 -> 2.3273241
A34: Muros laterales | B34: Y (±) | C34: =D16 -> 628.755 | D34: ='SPRFV - Cara Corta'!H14 -> -33.597114 | E34: =D34*C34 -> -21124.353 | F34: =E34/1000 -> -21.124353 | G34: ='SPRFV - Cara Corta'!H24 -> -17.990713 | H34: =G34*C34 -> -11311.75 | I34: =H34/1000 -> -11.31175
A35: Techo zona 1 (0 a h/2) | B35: Z (−) | C35: =D17 -> 342.40879 | D35: ='SPRFV - Cara Corta'!H15 -> -40.966803 | E35: =D35*C35 -> -14027.394 | F35: =E35/1000 -> -14.027394 | G35: ='SPRFV - Cara Corta'!H25 -> -25.360402 | H35: =G35*C35 -> -8683.6247 | I35: =H35/1000 -> -8.6836247
A36: Techo zona 2 (h/2 a h) | B36: Z (−) | C36: =D18 -> 342.40879 | D36: ='SPRFV - Cara Corta'!H16 -> -40.966803 | E36: =D36*C36 -> -14027.394 | F36: =E36/1000 -> -14.027394 | G36: ='SPRFV - Cara Corta'!H26 -> -25.360402 | H36: =G36*C36 -> -8683.6247 | I36: =H36/1000 -> -8.6836247
A37: Techo zona 3 (h a 2h) | B37: Z (−) | C37: =D19 -> 684.81759 | D37: ='SPRFV - Cara Corta'!H17 -> -26.227424 | E37: =D37*C37 -> -17961.002 | F37: =E37/1000 -> -17.961002 | G37: ='SPRFV - Cara Corta'!H27 -> -10.621023 | H37: =G37*C37 -> -7273.4634 | I37: =H37/1000 -> -7.2734634
A38: Techo zona 4 (> 2h) | B38: Z (−) | C38: =D20 -> 2811.1804 | D38: ='SPRFV - Cara Corta'!H18 -> -18.857735 | E38: =D38*C38 -> -53012.494 | F38: =E38/1000 -> -53.012494 | G38: ='SPRFV - Cara Corta'!H28 -> -3.2513336 | H38: =G38*C38 -> -9140.0852 | I38: =H38/1000 -> -9.1400852
A39: ∑ RESULTANTE CARA CORTA (eje X) | B39: X | E39: =E32+E33 -> 17594.286 | F39: =F32+F33 -> 17.594286 | H39: =H32+H33 -> 17594.286 | I39: =I32+I33 -> 17.594286
A40: ∑ TECHO CARA CORTA (eje Z) | B40: Z | E40: =E35+E36+E37+E38 -> -99028.283 | F40: =F35+F36+F37+F38 -> -99.028283 | H40: =H35+H36+H37+H38 -> -33780.798 | I40: =I35+I36+I37+I38 -> -33.780798
A42: VIENTO ⊥ CARA LARGA (dir. Y)
A43: Muro barlovento | B43: Y (+) | C43: =D22 -> 628.755 | D43: ='SPRFV - Cara Larga'!H12 -> 21.675557 | E43: =D43*C43 -> 13628.615 | F43: =E43/1000 -> 13.628615 | G43: ='SPRFV - Cara Larga'!H22 -> 37.281959 | H43: =G43*C43 -> 23441.218 | I43: =H43/1000 -> 23.441218
A44: Muro sotavento | B44: Y (+) | C44: =D22 -> 628.755 | D44: =-'SPRFV - Cara Larga'!H13 -> 26.227424 | E44: =D44*C44 -> 16490.624 | F44: =E44/1000 -> 16.490624 | G44: =-'SPRFV - Cara Larga'!H23 -> 10.621023 | H44: =G44*C44 -> 6678.0214 | I44: =H44/1000 -> 6.6780214
...

Sheet FUERZAS SAP2000
A1: TABLE: Base Reactions
A2: OutputCase | B2: CaseType | C2: GlobalFX | D2: GlobalFY | E2: GlobalFZ | F2: GlobalMX | G2: GlobalMY | H2: GlobalMZ
A3: Text | B3: Text | C3: Tonf | D3: Tonf | E3: Tonf | F3: Tonf-m | G3: Tonf-m | H3: Tonf-m
A4: Wx+ | B4: LinStatic | C4: -17.5818 | D4: 1.295e-06 | E4: -90.5225 | F4: -2263.0637 | G4: 3284.7824 | H4: 439.59232
A5: Wx- | B5: LinStatic | C5: -17.5818 | D5: 1.229e-06 | E5: -25.3658 | F5: -634.14553 | G5: 564.48914 | H5: 439.59231
A6: Wy+ | B6: LinStatic | C6: -2.554e-14 | D6: -29.0795 | E6: -98.4229 | F6: -1981.1865 | G6: 4109.1541 | H6: -1214.0876
A7: Wy- | B7: LinStatic | C7: -2.134e-14 | D7: -29.0795 | E7: -33.2661 | F7: -352.2684 | G7: 1388.8608 | H7: -1214.0876
